{
 "cells": [
  {
   "cell_type": "code",
   "execution_count": null,
   "id": "5a157ff5-dc83-4ff7-a647-01891f287a10",
   "metadata": {},
   "outputs": [],
   "source": [
    "# Q.1 What is Exception in python ? what is the difference between Exception and syntax error?\n",
    "\n",
    "# Ans: Exception : Exceptions are raised when the syntax of the program is correct but the code resulted in an error.\n",
    "#               This error does not stop the execution of the program, however, it changes the normal flow of the program.\n",
    "    \n",
    "#     for example: \n",
    "\n",
    "a = [1, 2, 3]\n",
    "try: \n",
    "    print (\"Second element = %d\" %(a[1]))\n",
    "  \n",
    "    # Throws error since there are only 3 elements in array\n",
    "    print (\"Fourth element = %d\" %(a[3]))\n",
    "  \n",
    "except Exception as e:\n",
    "    print (e)\n",
    "    \n",
    "    \n",
    "    \n",
    "#     Syntax error : When the syntax of the program is wrong or incorrect then this error happens. It leads to the termination \n",
    "#                    of the program\n",
    "    \n",
    "#     for example:\n",
    "\n",
    "print(\"hello world)"
   ]
  },
  {
   "cell_type": "code",
   "execution_count": null,
   "id": "c55da273-043b-40cb-8c25-45530e634a55",
   "metadata": {},
   "outputs": [],
   "source": [
    "# Q.2: What happens when an Exception is not handled ? Explain with an Example.\n",
    "\n",
    "# Ans : when we do not handle exception in a program , in result the program to terminates suddenly, and an error \n",
    "#       massagge is displayed to the user. It can be objectional, especially when working with critical systems like\n",
    "#       medical, finance sytem etc.\n",
    "        \n",
    "#     for example: In the given example we are trying to add an integer value with a string. This causes a TypeError \n",
    "                    # exception to be raised. Since we have not provided any error handling mechanism in the code, the \n",
    "                    # program will terminate abruptly with the following error message:\n",
    "        \n",
    "a = 123\n",
    "b = \"pwskills\"\n",
    "c = 123 + \"pwskills\"\n",
    "print(c)"
   ]
  },
  {
   "cell_type": "code",
   "execution_count": null,
   "id": "58f67500-7dcd-46c8-99e8-16be0b34aa51",
   "metadata": {},
   "outputs": [],
   "source": [
    "# Q.3: Which python statement is used to handle exception in python? Explain with an Example.\n",
    "\n",
    "# Ans: the \"try\" and \"Except\" statement is used to handle exception in python. where, try clause contains the block\n",
    "#      of code that can raise an exception, while the except block contain the lines of code that handle the exception. \n",
    "    \n",
    "#     for Example: In this Example we write a block of code in try clause which open a file \"new.txt\" in read mode. if \n",
    "                   # file \"new.txt\" dosen't exist then try clause throw an exception which is handled by Except clause.\n",
    "    \n",
    "    \n",
    "try:        \n",
    "    with open(\"new.txt\", \"r\") as f:\n",
    "        f.read()\n",
    "except FileNotFoundError as e:\n",
    "    print(f\"File not found :\", e)"
   ]
  },
  {
   "cell_type": "code",
   "execution_count": null,
   "id": "1ab8ab3c-088b-4c9f-9d26-9516ef9a75c6",
   "metadata": {},
   "outputs": [],
   "source": [
    "# Q.4 Explain with an Example: \n",
    "#     1 try and except\n",
    "#     2 finally\n",
    "#     3 raise\n",
    "\n",
    "# Ans\n",
    "\n",
    "# 1 try and except : the \"try\" and \"Except\" statement is used to handle exception in python. where, try clause contains \n",
    "#                    the blockof code that can raise an exception, while the except block contain the lines of code that\n",
    "#                     handle the exception. \n",
    "    \n",
    "#     for Example: In this Example we write a block of code in try clause which open a file \"new.txt\" in read mode. if \n",
    "                   # file \"new.txt\" dosen't exist then try clause throw an exception which is handled by Except clause.\n",
    "        \n",
    "try:        \n",
    "    with open(\"new.txt\", \"r\") as f:\n",
    "        f.read()\n",
    "except Exception as e:\n",
    "    print(e)\n",
    "\n",
    "    \n",
    "# 2 finally : In python, The finally statement is used in exception handling. the code of finally will be executed after the \n",
    "#             block of code inside try and except have been excuted. the code of finally will be executed regardless wheather\n",
    "#             an exception is raised or not\n",
    "        \n",
    "#             The finally is used to release the connections like : open file, database connection, etc. it is also ensure that\n",
    "#             some specific code will be executed, wheather the extion an exception is raised or not.\n",
    "    \n",
    "#     for Example: In this example 5 is divided by 0 which gives ZeroDivisionError but still the code in finally block is executed\n",
    "try:\n",
    "    k = 5/0 # raises divide by zero exception.\n",
    "    print(k)\n",
    "  \n",
    "\n",
    "except ZeroDivisionError:   \n",
    "    print(\"Can't divide by zero\")\n",
    "      \n",
    "finally:\n",
    "    # this block is always executed \n",
    "    # regardless of exception generation.\n",
    "    print('This is always executed') \n",
    "\n",
    "\n",
    "# # 3 raise : The raise statement is used to throw an exception or error and stops the program at any time if the certain condition\n",
    "#              doesn't meet. When we use raise statement. there is no compulsion to give an exception class along with it. \n",
    "        \n",
    "#              Raise allows us to throw one exception at any time. It helps us raise exceptions when we may run into situations where\n",
    "#              execution canâ€™t proceed. It also helps us in reraise exception that is caught.\n",
    "    \n",
    "#       for Example: In this example the conditions doesn't match and raise statement throws an exception in try clause, then by try \n",
    "#                     clause the exception is handled by the except clause.\n",
    "        \n",
    "x = -1\n",
    "try:\n",
    "    if x < 0:\n",
    "      raise Exception(\"Sorry, no numbers below zero\")\n",
    "except Exception as e:\n",
    "    print(e)\n",
    "    "
   ]
  },
  {
   "cell_type": "code",
   "execution_count": null,
   "id": "a9a04f7a-b9e3-48d0-9ff3-cedd8162ca7a",
   "metadata": {},
   "outputs": [],
   "source": [
    "# Q.5 : What are custom exception in python? why do we need custom exception? Explain with an example.\n",
    "\n",
    "# Ans: In python, a custom exception is a user- defined exception, that can be raised like build in exception.\n",
    "#      It allows us to define their own exception which is useful in specific situations.\n",
    "\n",
    "#         It is useful to create custom exception when the built-in exception do not provide enough information or\n",
    "#         context about the error.\n",
    "        \n",
    "#         the custom exception class is created by inherating the built-in \"Exception\" class or any of its derived classes\n",
    "#         in the base class. once a custom exception class has been defined. it can be raised using \"raise\" statement.    \n",
    "\n",
    "        \n",
    "#     for Example:\n",
    "#             In this example, we have defined a custom exception NegativeNumberError that inherits from the Exception class.\n",
    "#             This custom exception takes a value argument and provides a custom error message when a negative number is encountered.\n",
    "\n",
    "#               We have also defined a function square_root that calculates the square root of a given number. If the input number is\n",
    "#               negative, the NegativeNumberError is raised, which will be caught by the except block.\n",
    "\n",
    "#               When we call the square_root function with a negative number, it raises the NegativeNumberError, which is caught by the\n",
    "#             except block. The error message \" -1 is a negative number\" is printed to the console.\n",
    "\n",
    "class NegativeNumberError(Exception):\n",
    "    def __init__(self, value):\n",
    "        self.value = value\n",
    "\n",
    "    def __str__(self):\n",
    "        return f\"{self.value} is a negative number\"\n",
    "\n",
    "\n",
    "def square_root(num):\n",
    "    if num < 0:\n",
    "        raise NegativeNumberError(num)\n",
    "    else:\n",
    "        return num ** 0.5\n",
    "\n",
    "\n",
    "try:\n",
    "    result = square_root(-1)\n",
    "    print(result)\n",
    "except NegativeNumberError as e:\n",
    "    print(e)\n",
    "    "
   ]
  },
  {
   "cell_type": "code",
   "execution_count": null,
   "id": "2b9f68ed-8175-4d14-bee6-e14beafbe8f5",
   "metadata": {},
   "outputs": [],
   "source": [
    "# Q.6: Create a custom exception class. use this class to handle an exception.\n",
    "\n",
    "# Ans: \n",
    "class NegativeNumberError(Exception):\n",
    "    def __init__(self, value):\n",
    "        self.value = value\n",
    "\n",
    "    def __str__(self):\n",
    "        return f\"{self.value} is a negative number\"\n",
    "\n",
    "\n",
    "def square_root(num):\n",
    "    if num < 0:\n",
    "        raise NegativeNumberError(num)\n",
    "    else:\n",
    "        return num ** 0.5\n",
    "\n",
    "\n",
    "try:\n",
    "    result = square_root(-1)\n",
    "    print(result)\n",
    "except NegativeNumberError as e:\n",
    "    print(e)\n",
    "    "
   ]
  }
 ],
 "metadata": {
  "kernelspec": {
   "display_name": "Python 3 (ipykernel)",
   "language": "python",
   "name": "python3"
  },
  "language_info": {
   "codemirror_mode": {
    "name": "ipython",
    "version": 3
   },
   "file_extension": ".py",
   "mimetype": "text/x-python",
   "name": "python",
   "nbconvert_exporter": "python",
   "pygments_lexer": "ipython3",
   "version": "3.10.6"
  }
 },
 "nbformat": 4,
 "nbformat_minor": 5
}
